Traceback (most recent call last):
  File "/Users/narizuka/.pyenv/versions/miniforge3-4.10.3-10/envs/myenv/lib/python3.9/site-packages/jupyter_cache/executors/utils.py", line 51, in single_nb_execution
    executenb(
  File "/Users/narizuka/.pyenv/versions/miniforge3-4.10.3-10/envs/myenv/lib/python3.9/site-packages/nbclient/client.py", line 1204, in execute
    return NotebookClient(nb=nb, resources=resources, km=km, **kwargs).execute()
  File "/Users/narizuka/.pyenv/versions/miniforge3-4.10.3-10/envs/myenv/lib/python3.9/site-packages/nbclient/util.py", line 84, in wrapped
    return just_run(coro(*args, **kwargs))
  File "/Users/narizuka/.pyenv/versions/miniforge3-4.10.3-10/envs/myenv/lib/python3.9/site-packages/nbclient/util.py", line 62, in just_run
    return loop.run_until_complete(coro)
  File "/Users/narizuka/.pyenv/versions/miniforge3-4.10.3-10/envs/myenv/lib/python3.9/asyncio/base_events.py", line 647, in run_until_complete
    return future.result()
  File "/Users/narizuka/.pyenv/versions/miniforge3-4.10.3-10/envs/myenv/lib/python3.9/site-packages/nbclient/client.py", line 663, in async_execute
    await self.async_execute_cell(
  File "/Users/narizuka/.pyenv/versions/miniforge3-4.10.3-10/envs/myenv/lib/python3.9/site-packages/nbclient/client.py", line 965, in async_execute_cell
    await self._check_raise_for_error(cell, cell_index, exec_reply)
  File "/Users/narizuka/.pyenv/versions/miniforge3-4.10.3-10/envs/myenv/lib/python3.9/site-packages/nbclient/client.py", line 862, in _check_raise_for_error
    raise CellExecutionError.from_cell_and_msg(cell, exec_reply_content)
nbclient.exceptions.CellExecutionError: An error occurred while executing the following cell:
------------------
import sys, os
import numpy as np
import matplotlib.pyplot as plt
# import japanize_matplotlib
import pandas as pd
from pandas import DataFrame
pd.set_option('display.precision', 3)   # Â∞èÊï∞ÁÇπ‰ª•‰∏ã„ÅÆË°®Á§∫Ê°Å
pd.set_option('display.max_rows', 20)  # Ë°®Á§∫„Åô„ÇãË°åÊï∞
precision 3
------------------

[0;36m  Input [0;32mIn [1][0;36m[0m
[0;31m    precision 3[0m
[0m              ^[0m
[0;31mSyntaxError[0m[0;31m:[0m invalid syntax

SyntaxError: invalid syntax (804670368.py, line 9)

